[2024-09-25T16:48:15.171+0000] {local_task_job_runner.py:120} INFO - ::group::Pre task execution logs
[2024-09-25T16:48:15.190+0000] {taskinstance.py:2073} INFO - Dependencies all met for dep_context=non-requeueable deps ti=<TaskInstance: upload_from_api.execute_notebook manual__2024-09-25T16:48:06.920068+00:00 [queued]>
[2024-09-25T16:48:15.198+0000] {taskinstance.py:2073} INFO - Dependencies all met for dep_context=requeueable deps ti=<TaskInstance: upload_from_api.execute_notebook manual__2024-09-25T16:48:06.920068+00:00 [queued]>
[2024-09-25T16:48:15.199+0000] {taskinstance.py:2303} INFO - Starting attempt 1 of 1
[2024-09-25T16:48:15.214+0000] {taskinstance.py:2327} INFO - Executing <Task(BashOperator): execute_notebook> on 2024-09-25 16:48:06.920068+00:00
[2024-09-25T16:48:15.222+0000] {warnings.py:110} WARNING - /home/***/.local/lib/python3.12/site-packages/***/task/task_runner/standard_task_runner.py:61: DeprecationWarning: This process (pid=2270) is multi-threaded, use of fork() may lead to deadlocks in the child.
  pid = os.fork()

[2024-09-25T16:48:15.224+0000] {standard_task_runner.py:63} INFO - Started process 2272 to run task
[2024-09-25T16:48:15.224+0000] {standard_task_runner.py:90} INFO - Running: ['***', 'tasks', 'run', 'upload_from_api', 'execute_notebook', 'manual__2024-09-25T16:48:06.920068+00:00', '--job-id', '4', '--raw', '--subdir', 'DAGS_FOLDER/upload_from_api.py', '--cfg-path', '/tmp/tmpw0yk7f5a']
[2024-09-25T16:48:15.227+0000] {standard_task_runner.py:91} INFO - Job 4: Subtask execute_notebook
[2024-09-25T16:48:15.278+0000] {task_command.py:426} INFO - Running <TaskInstance: upload_from_api.execute_notebook manual__2024-09-25T16:48:06.920068+00:00 [running]> on host 1543f9e1f847
[2024-09-25T16:48:15.385+0000] {taskinstance.py:2644} INFO - Exporting env vars: AIRFLOW_CTX_DAG_EMAIL='ricardo.cauduro@outlook.com' AIRFLOW_CTX_DAG_OWNER='rica7' AIRFLOW_CTX_DAG_ID='upload_from_api' AIRFLOW_CTX_TASK_ID='execute_notebook' AIRFLOW_CTX_EXECUTION_DATE='2024-09-25T16:48:06.920068+00:00' AIRFLOW_CTX_TRY_NUMBER='1' AIRFLOW_CTX_DAG_RUN_ID='manual__2024-09-25T16:48:06.920068+00:00'
[2024-09-25T16:48:15.386+0000] {taskinstance.py:430} INFO - ::endgroup::
[2024-09-25T16:48:15.399+0000] {subprocess.py:63} INFO - Tmp dir root location: /tmp
[2024-09-25T16:48:15.400+0000] {subprocess.py:75} INFO - Running command: ['/usr/bin/bash', '-c', 'docker exec ***-jupyter-1 sh -c \'pip install pyarrow && pip install findspark && pip install hdfs3 && pip install papermill && papermill /home/jovyan/work/teste.ipynb /home/jovyan/work/out_teste.ipynb -p date "20240925164812"\'']
[2024-09-25T16:48:15.411+0000] {subprocess.py:86} INFO - Output:
[2024-09-25T16:48:15.563+0000] {subprocess.py:93} INFO - Error response from daemon: No such container: ***-jupyter-1
[2024-09-25T16:48:15.564+0000] {subprocess.py:97} INFO - Command exited with return code 1
[2024-09-25T16:48:15.565+0000] {taskinstance.py:441} INFO - ::group::Post task execution logs
[2024-09-25T16:48:15.573+0000] {taskinstance.py:2890} ERROR - Task failed with exception
Traceback (most recent call last):
  File "/home/airflow/.local/lib/python3.12/site-packages/airflow/models/taskinstance.py", line 465, in _execute_task
    result = _execute_callable(context=context, **execute_callable_kwargs)
             ^^^^^^^^^^^^^^^^^^^^^^^^^^^^^^^^^^^^^^^^^^^^^^^^^^^^^^^^^^^^^
  File "/home/airflow/.local/lib/python3.12/site-packages/airflow/models/taskinstance.py", line 432, in _execute_callable
    return execute_callable(context=context, **execute_callable_kwargs)
           ^^^^^^^^^^^^^^^^^^^^^^^^^^^^^^^^^^^^^^^^^^^^^^^^^^^^^^^^^^^^
  File "/home/airflow/.local/lib/python3.12/site-packages/airflow/models/baseoperator.py", line 400, in wrapper
    return func(self, *args, **kwargs)
           ^^^^^^^^^^^^^^^^^^^^^^^^^^^
  File "/home/airflow/.local/lib/python3.12/site-packages/airflow/operators/bash.py", line 243, in execute
    raise AirflowException(
airflow.exceptions.AirflowException: Bash command failed. The command returned a non-zero exit code 1.
[2024-09-25T16:48:15.577+0000] {taskinstance.py:1205} INFO - Marking task as FAILED. dag_id=upload_from_api, task_id=execute_notebook, execution_date=20240925T164806, start_date=20240925T164815, end_date=20240925T164815
[2024-09-25T16:48:15.594+0000] {warnings.py:110} WARNING - /home/***/.local/lib/python3.12/site-packages/***/utils/email.py:154: RemovedInAirflow3Warning: Fetching SMTP credentials from configuration variables will be deprecated in a future release. Please set credentials using a connection instead.
  send_mime_email(e_from=mail_from, e_to=recipients, mime_msg=msg, conn_id=conn_id, dryrun=dryrun)

[2024-09-25T16:48:15.595+0000] {configuration.py:1050} WARNING - section/key [smtp/smtp_user] not found in config
[2024-09-25T16:48:15.596+0000] {email.py:271} INFO - Email alerting: attempt 1
[2024-09-25T16:48:15.606+0000] {configuration.py:1050} WARNING - section/key [smtp/smtp_user] not found in config
[2024-09-25T16:48:15.607+0000] {email.py:271} INFO - Email alerting: attempt 1
[2024-09-25T16:48:15.608+0000] {taskinstance.py:879} ERROR - Failed to send email to: ['ricardo.cauduro@outlook.com']
Traceback (most recent call last):
  File "/home/airflow/.local/lib/python3.12/site-packages/airflow/models/taskinstance.py", line 2476, in _run_raw_task
    self._execute_task_with_callbacks(context, test_mode, session=session)
  File "/home/airflow/.local/lib/python3.12/site-packages/airflow/models/taskinstance.py", line 2663, in _execute_task_with_callbacks
    result = self._execute_task(context, task_orig)
             ^^^^^^^^^^^^^^^^^^^^^^^^^^^^^^^^^^^^^^
  File "/home/airflow/.local/lib/python3.12/site-packages/airflow/models/taskinstance.py", line 2686, in _execute_task
    return _execute_task(self, context, task_orig)
           ^^^^^^^^^^^^^^^^^^^^^^^^^^^^^^^^^^^^^^^
  File "/home/airflow/.local/lib/python3.12/site-packages/airflow/models/taskinstance.py", line 465, in _execute_task
    result = _execute_callable(context=context, **execute_callable_kwargs)
             ^^^^^^^^^^^^^^^^^^^^^^^^^^^^^^^^^^^^^^^^^^^^^^^^^^^^^^^^^^^^^
  File "/home/airflow/.local/lib/python3.12/site-packages/airflow/models/taskinstance.py", line 432, in _execute_callable
    return execute_callable(context=context, **execute_callable_kwargs)
           ^^^^^^^^^^^^^^^^^^^^^^^^^^^^^^^^^^^^^^^^^^^^^^^^^^^^^^^^^^^^
  File "/home/airflow/.local/lib/python3.12/site-packages/airflow/models/baseoperator.py", line 400, in wrapper
    return func(self, *args, **kwargs)
           ^^^^^^^^^^^^^^^^^^^^^^^^^^^
  File "/home/airflow/.local/lib/python3.12/site-packages/airflow/operators/bash.py", line 243, in execute
    raise AirflowException(
airflow.exceptions.AirflowException: Bash command failed. The command returned a non-zero exit code 1.

During handling of the above exception, another exception occurred:

Traceback (most recent call last):
  File "/home/airflow/.local/lib/python3.12/site-packages/airflow/models/taskinstance.py", line 1063, in _email_alert
    send_email(task.email, subject, html_content)
  File "/home/airflow/.local/lib/python3.12/site-packages/airflow/utils/email.py", line 80, in send_email
    return backend(
           ^^^^^^^^
  File "/home/airflow/.local/lib/python3.12/site-packages/airflow/utils/email.py", line 154, in send_email_smtp
    send_mime_email(e_from=mail_from, e_to=recipients, mime_msg=msg, conn_id=conn_id, dryrun=dryrun)
  File "/home/airflow/.local/lib/python3.12/site-packages/airflow/utils/email.py", line 273, in send_mime_email
    smtp_conn = _get_smtp_connection(smtp_host, smtp_port, smtp_timeout, smtp_ssl)
                ^^^^^^^^^^^^^^^^^^^^^^^^^^^^^^^^^^^^^^^^^^^^^^^^^^^^^^^^^^^^^^^^^^
  File "/home/airflow/.local/lib/python3.12/site-packages/airflow/utils/email.py", line 317, in _get_smtp_connection
    return smtplib.SMTP(host=host, port=port, timeout=timeout)
           ^^^^^^^^^^^^^^^^^^^^^^^^^^^^^^^^^^^^^^^^^^^^^^^^^^^
  File "/usr/local/lib/python3.12/smtplib.py", line 255, in __init__
    (code, msg) = self.connect(host, port)
                  ^^^^^^^^^^^^^^^^^^^^^^^^
  File "/usr/local/lib/python3.12/smtplib.py", line 341, in connect
    self.sock = self._get_socket(host, port, self.timeout)
                ^^^^^^^^^^^^^^^^^^^^^^^^^^^^^^^^^^^^^^^^^^
  File "/usr/local/lib/python3.12/smtplib.py", line 312, in _get_socket
    return socket.create_connection((host, port), timeout,
           ^^^^^^^^^^^^^^^^^^^^^^^^^^^^^^^^^^^^^^^^^^^^^^^
  File "/usr/local/lib/python3.12/socket.py", line 852, in create_connection
    raise exceptions[0]
  File "/usr/local/lib/python3.12/socket.py", line 837, in create_connection
    sock.connect(sa)
ConnectionRefusedError: [Errno 111] Connection refused

During handling of the above exception, another exception occurred:

Traceback (most recent call last):
  File "/home/airflow/.local/lib/python3.12/site-packages/airflow/models/taskinstance.py", line 877, in _handle_failure
    task_instance.email_alert(error, failure_context["task"])
  File "/home/airflow/.local/lib/python3.12/site-packages/airflow/models/taskinstance.py", line 3148, in email_alert
    _email_alert(task_instance=self, exception=exception, task=task)
  File "/home/airflow/.local/lib/python3.12/site-packages/airflow/models/taskinstance.py", line 1065, in _email_alert
    send_email(task.email, subject, html_content_err)
  File "/home/airflow/.local/lib/python3.12/site-packages/airflow/utils/email.py", line 80, in send_email
    return backend(
           ^^^^^^^^
  File "/home/airflow/.local/lib/python3.12/site-packages/airflow/utils/email.py", line 154, in send_email_smtp
    send_mime_email(e_from=mail_from, e_to=recipients, mime_msg=msg, conn_id=conn_id, dryrun=dryrun)
  File "/home/airflow/.local/lib/python3.12/site-packages/airflow/utils/email.py", line 273, in send_mime_email
    smtp_conn = _get_smtp_connection(smtp_host, smtp_port, smtp_timeout, smtp_ssl)
                ^^^^^^^^^^^^^^^^^^^^^^^^^^^^^^^^^^^^^^^^^^^^^^^^^^^^^^^^^^^^^^^^^^
  File "/home/airflow/.local/lib/python3.12/site-packages/airflow/utils/email.py", line 317, in _get_smtp_connection
    return smtplib.SMTP(host=host, port=port, timeout=timeout)
           ^^^^^^^^^^^^^^^^^^^^^^^^^^^^^^^^^^^^^^^^^^^^^^^^^^^
  File "/usr/local/lib/python3.12/smtplib.py", line 255, in __init__
    (code, msg) = self.connect(host, port)
                  ^^^^^^^^^^^^^^^^^^^^^^^^
  File "/usr/local/lib/python3.12/smtplib.py", line 341, in connect
    self.sock = self._get_socket(host, port, self.timeout)
                ^^^^^^^^^^^^^^^^^^^^^^^^^^^^^^^^^^^^^^^^^^
  File "/usr/local/lib/python3.12/smtplib.py", line 312, in _get_socket
    return socket.create_connection((host, port), timeout,
           ^^^^^^^^^^^^^^^^^^^^^^^^^^^^^^^^^^^^^^^^^^^^^^^
  File "/usr/local/lib/python3.12/socket.py", line 852, in create_connection
    raise exceptions[0]
  File "/usr/local/lib/python3.12/socket.py", line 837, in create_connection
    sock.connect(sa)
ConnectionRefusedError: [Errno 111] Connection refused
[2024-09-25T16:48:15.629+0000] {standard_task_runner.py:110} ERROR - Failed to execute job 4 for task execute_notebook (Bash command failed. The command returned a non-zero exit code 1.; 2272)
[2024-09-25T16:48:15.639+0000] {local_task_job_runner.py:240} INFO - Task exited with return code 1
[2024-09-25T16:48:15.658+0000] {taskinstance.py:3482} INFO - 0 downstream tasks scheduled from follow-on schedule check
[2024-09-25T16:48:15.662+0000] {local_task_job_runner.py:222} INFO - ::endgroup::
